Workbook

Sheet AAPL DATA
B2: AAPL
B3: Date | C3: Open | D3: High | E3: Low | F3: Close | G3: Volume
B4: 01/03/2023 16:00:00 | C4: 146.83 | D4: 147.23 | E4: 145.01 | F4: 145.31 | G4: 55478991
B5: 02/03/2023 16:00:00 | C5: 144.38 | D5: 146.71 | E5: 143.9 | F5: 145.91 | G5: 52279761
B6: 03/03/2023 16:00:00 | C6: 148.04 | D6: 151.11 | E6: 147.33 | F6: 151.03 | G6: 70732297
B7: 06/03/2023 16:00:00 | C7: 153.79 | D7: 156.3 | E7: 153.46 | F7: 153.83 | G7: 87558028
B8: 07/03/2023 16:00:00 | C8: 153.7 | D8: 154.03 | E8: 151.13 | F8: 151.6 | G8: 56182028
B9: 08/03/2023 16:00:00 | C9: 152.81 | D9: 153.47 | E9: 151.83 | F9: 152.87 | G9: 47204791
B10: 09/03/2023 16:00:00 | C10: 153.56 | D10: 154.54 | E10: 150.23 | F10: 150.59 | G10: 53833582
B11: 10/03/2023 16:00:00 | C11: 150.21 | D11: 150.94 | E11: 147.61 | F11: 148.5 | G11: 68572400
B12: 13/03/2023 16:00:00 | C12: 147.81 | D12: 153.14 | E12: 147.7 | F12: 150.47 | G12: 84457122
B13: 14/03/2023 16:00:00 | C13: 151.28 | D13: 153.4 | E13: 150.1 | F13: 152.59 | G13: 73695893
B14: 15/03/2023 16:00:00 | C14: 151.19 | D14: 153.25 | E14: 149.92 | F14: 152.99 | G14: 77167866
B15: 16/03/2023 16:00:00 | C15: 152.16 | D15: 156.46 | E15: 151.64 | F15: 155.85 | G15: 76254419
... B505: 28/02/2025 16:00:00 | C505: 236.95 | D505: 242.09 | E505: 230.2 | F505: 241.84 | G505: 56833360

Sheet AMZN DATA
B1: AMZN
B2: Date | C2: Open | D2: High | E2: Low | F2: Close | G2: Volume
B3: 01/03/2023 16:00:00 | C3: 93.87 | D3: 94.68 | E3: 91.59 | F3: 92.17 | G3: 52299524
B4: 02/03/2023 16:00:00 | C4: 91.41 | D4: 92.23 | E4: 90.39 | F4: 92.13 | G4: 55574820
B5: 03/03/2023 16:00:00 | C5: 92.74 | D5: 94.94 | E5: 92.66 | F5: 94.9 | G5: 55759609
B6: 06/03/2023 16:00:00 | C6: 95.19 | D6: 96.55 | E6: 93.74 | F6: 93.75 | G6: 52112355
B7: 07/03/2023 16:00:00 | C7: 94.06 | D7: 95.09 | E7: 92.78 | F7: 93.55 | G7: 49100668
B8: 08/03/2023 16:00:00 | C8: 93.6 | D8: 94.17 | E8: 92.18 | F8: 93.92 | G8: 44899128
B9: 09/03/2023 16:00:00 | C9: 93.68 | D9: 96.21 | E9: 92.18 | F9: 92.25 | G9: 56218705
B10: 10/03/2023 16:00:00 | C10: 92.67 | D10: 93.57 | E10: 90.25 | F10: 90.73 | G10: 69827490
B11: 13/03/2023 16:00:00 | C11: 89.97 | D11: 94.02 | E11: 88.12 | F11: 92.43 | G11: 72397053
B12: 14/03/2023 16:00:00 | C12: 93.83 | D12: 95.07 | E12: 92.71 | F12: 94.88 | G12: 60912674
B13: 15/03/2023 16:00:00 | C13: 93.22 | D13: 96.67 | E13: 93.07 | F13: 96.2 | G13: 70731792
B14: 16/03/2023 16:00:00 | C14: 95.75 | D14: 100.99 | E14: 95.61 | F14: 100.04 | G14: 84558934
... B504: 28/02/2025 16:00:00 | C504: 208.65 | D504: 212.62 | E504: 206.99 | F504: 212.28 | G504: 51771737

Sheet CVX DATA
B2: CVX
B3: Date | C3: Open | D3: High | E3: Low | F3: Close | G3: Volume
B4: 01/03/2023 16:00:00 | C4: 160.92 | D4: 163.59 | E4: 160.59 | F4: 162.05 | G4: 7470391
B5: 02/03/2023 16:00:00 | C5: 161.98 | D5: 163.49 | E5: 161.59 | F5: 162.56 | G5: 5582097
B6: 03/03/2023 16:00:00 | C6: 160.87 | D6: 165.58 | E6: 160.42 | F6: 164.96 | G6: 6007546
B7: 06/03/2023 16:00:00 | C7: 164.34 | D7: 166.8 | E7: 163.81 | F7: 166.17 | G7: 7703600
B8: 07/03/2023 16:00:00 | C8: 165.7 | D8: 166.6 | E8: 163.58 | F8: 164.03 | G8: 7392967
B9: 08/03/2023 16:00:00 | C9: 163.23 | D9: 165.29 | E9: 161.38 | F9: 162.99 | G9: 5435819
B10: 09/03/2023 16:00:00 | C10: 163.79 | D10: 165.49 | E10: 160.19 | F10: 160.51 | G10: 6214745
B11: 10/03/2023 16:00:00 | C11: 160.94 | D11: 164.67 | E11: 158.67 | F11: 159.67 | G11: 7385803
B12: 13/03/2023 16:00:00 | C12: 156.44 | D12: 160.95 | E12: 153.8 | F12: 158.71 | G12: 10106133
B13: 14/03/2023 16:00:00 | C13: 158.26 | D13: 164.02 | E13: 157.88 | F13: 160.76 | G13: 10035193
B14: 15/03/2023 16:00:00 | C14: 155.59 | D14: 157.95 | E14: 152.01 | F14: 153.8 | G14: 14063141
B15: 16/03/2023 16:00:00 | C15: 150.16 | D15: 155.47 | E15: 149.91 | F15: 154.29 | G15: 12852173
... B505: 28/02/2025 16:00:00 | C505: 156.7 | D505: 158.67 | E505: 154.92 | F505: 158.62 | G505: 8828547

Sheet WDC DATA
B2: WDC
B3: Date | C3: Open | D3: High | E3: Low | F3: Close | G3: Volume
B4: 01/03/2023 16:00:00 | C4: 29.19 | D4: 29.36 | E4: 28.71 | F4: 28.81 | G4: 3631862
B5: 02/03/2023 16:00:00 | C5: 28.6 | D5: 29.12 | E5: 28.1 | F5: 29.01 | G5: 2590690
B6: 03/03/2023 16:00:00 | C6: 29.03 | D6: 29.33 | E6: 28.88 | F6: 29.17 | G6: 2261242
B7: 06/03/2023 16:00:00 | C7: 29.3 | D7: 29.36 | E7: 28.47 | F7: 28.56 | G7: 6189265
B8: 07/03/2023 16:00:00 | C8: 28.45 | D8: 28.55 | E8: 28 | F8: 28.2 | G8: 4126948
B9: 08/03/2023 16:00:00 | C9: 28.3 | D9: 28.67 | E9: 28.14 | F9: 28.65 | G9: 2463445
B10: 09/03/2023 16:00:00 | C10: 28.65 | D10: 28.98 | E10: 28 | F10: 28.01 | G10: 2663292
B11: 10/03/2023 16:00:00 | C11: 27.94 | D11: 28 | E11: 27.03 | F11: 27.26 | G11: 5367756
B12: 13/03/2023 16:00:00 | C12: 26.66 | D12: 27.07 | E12: 26.08 | F12: 26.7 | G12: 8292159
B13: 14/03/2023 16:00:00 | C13: 27.3 | D13: 27.49 | E13: 26.42 | F13: 26.67 | G13: 3995548
B14: 15/03/2023 16:00:00 | C14: 25.96 | D14: 26.42 | E14: 25.61 | F14: 25.99 | G14: 4433619
B15: 16/03/2023 16:00:00 | C15: 25.59 | D15: 26.82 | E15: 25.51 | F15: 26.71 | G15: 4931336
... B505: 28/02/2025 16:00:00 | C505: 48.33 | D505: 50.08 | E505: 48 | F505: 48.93 | G505: 9268624

Sheet MA DATA
B2: MA
B3: Date | C3: Open | D3: High | E3: Low | F3: Close | G3: Volume
B4: 01/03/2023 16:00:00 | C4: 354 | D4: 355.31 | E4: 349.39 | F4: 353.5 | G4: 1968084
B5: 02/03/2023 16:00:00 | C5: 353.63 | D5: 356.62 | E5: 351.69 | F5: 355.57 | G5: 2526001
B6: 03/03/2023 16:00:00 | C6: 358.12 | D6: 361.69 | E6: 357.09 | F6: 361.5 | G6: 2174952
B7: 06/03/2023 16:00:00 | C7: 361.82 | D7: 368.53 | E7: 361.26 | F7: 366.93 | G7: 2789640
B8: 07/03/2023 16:00:00 | C8: 367.17 | D8: 369.15 | E8: 359.55 | F8: 359.94 | G8: 1660771
B9: 08/03/2023 16:00:00 | C9: 358.61 | D9: 361.7 | E9: 357.28 | F9: 359.03 | G9: 1634442
B10: 09/03/2023 16:00:00 | C10: 359.25 | D10: 364.02 | E10: 353.91 | F10: 354.44 | G10: 2414831
B11: 10/03/2023 16:00:00 | C11: 352.41 | D11: 353.05 | E11: 345.23 | F11: 347.11 | G11: 3176505
B12: 13/03/2023 16:00:00 | C12: 343.63 | D12: 349.86 | E12: 340.21 | F12: 344.71 | G12: 3308396
B13: 14/03/2023 16:00:00 | C13: 351 | D13: 356.11 | E13: 348.56 | F13: 352.82 | G13: 3413323
B14: 15/03/2023 16:00:00 | C14: 346.05 | D14: 348.4 | E14: 343.64 | F14: 348.08 | G14: 3082755
B15: 16/03/2023 16:00:00 | C15: 346.62 | D15: 348.69 | E15: 340.28 | F15: 348 | G15: 3768216
... B505: 28/02/2025 16:00:00 | C505: 567.3 | D505: 576.43 | E505: 564 | F505: 576.31 | G505: 3205380

Sheet CEG DATA
B2: CEG
B3: Date | C3: Open | D3: High | E3: Low | F3: Close | G3: Volume
B4: 01/03/2023 16:00:00 | C4: 74.13 | D4: 75.39 | E4: 72.83 | F4: 74.35 | G4: 2594368
B5: 02/03/2023 16:00:00 | C5: 74.13 | D5: 76.73 | E5: 74 | F5: 76.18 | G5: 1949886
B6: 03/03/2023 16:00:00 | C6: 76.23 | D6: 79.2 | E6: 76 | F6: 78.98 | G6: 2304756
B7: 06/03/2023 16:00:00 | C7: 78.36 | D7: 78.88 | E7: 77.35 | F7: 78.8 | G7: 2294999
B8: 07/03/2023 16:00:00 | C8: 79.07 | D8: 79.07 | E8: 77.32 | F8: 77.9 | G8: 2203903
B9: 08/03/2023 16:00:00 | C9: 77.75 | D9: 78.45 | E9: 77.1 | F9: 78.07 | G9: 1261563
B10: 09/03/2023 16:00:00 | C10: 78.04 | D10: 80.19 | E10: 77.4 | F10: 78.64 | G10: 3110895
B11: 10/03/2023 16:00:00 | C11: 79.19 | D11: 79.78 | E11: 77.24 | F11: 77.55 | G11: 2895697
B12: 13/03/2023 16:00:00 | C12: 76.93 | D12: 78.61 | E12: 76.49 | F12: 77.1 | G12: 2242432
B13: 14/03/2023 16:00:00 | C13: 77.5 | D13: 79.1 | E13: 77.17 | F13: 77.93 | G13: 2142804
B14: 15/03/2023 16:00:00 | C14: 77.29 | D14: 77.88 | E14: 76.35 | F14: 77.33 | G14: 1956990
B15: 16/03/2023 16:00:00 | C15: 76.62 | D15: 79.04 | E15: 76.03 | F15: 78.43 | G15: 1966454
... B505: 28/02/2025 16:00:00 | C505: 246.42 | D505: 251.54 | E505: 241.61 | F505: 250.55 | G505: 6029597

Sheet % Change over timeframe
B1: AAPL | F1: AMZN | J1: CVX | N1: WDC | R1: MA | W1: CEG
B2: Day | C2: Close $ | D2: % Change DOD | F2: Day | G2: Close $ | H2: % Change DOD | J2: Day | K2: Close $ | L2: % Change DOD | N2: Day | O2: Close $ | P2: % Change DOD | R2: Day | S2: Close $ | T2: % Change DOD | W2: Day | X2: Close $ | Y2: % Change DOD
B3: ='CEG DATA'!B4 -> 01/03/2023 16:00:00 | C3: ='AAPL DATA'!F4 -> 145.31 | D3: =LN(C3/147.23) -> -0.013126599 | F3: =B3 -> 01/03/2023 16:00:00 | G3: ='AMZN DATA'!F3 -> 92.17 | H3: =LN(92.17/94.23) -> -0.022103904 | J3: =F3 -> 01/03/2023 16:00:00 | K3: ='CVX DATA'!F4 -> 162.05 | L3: =LN(K3/160.77) -> 0.0079301574 | N3: =J3 -> 01/03/2023 16:00:00 | O3: ='WDC DATA'!F4 -> 28.81 | P3: =LN(O3/29.09) -> -0.0096719234 | R3: =N3 -> 01/03/2023 16:00:00 | S3: ='MA DATA'!F4 -> 353.5 | T3: =LN(S3/355.29) -> -0.0050508721 | W3: =R3 -> 01/03/2023 16:00:00 | X3: ='CEG DATA'!F4 -> 74.35 | Y3: =LN(74.35/74.89) -> -0.0072366974
B4: ='CEG DATA'!B5 -> 02/03/2023 16:00:00 | C4: ='AAPL DATA'!F5 -> 145.91 | D4: =LN(C4/C3) -> 0.0041206019 | F4: =B4 -> 02/03/2023 16:00:00 | G4: ='AMZN DATA'!F4 -> 92.13 | H4: =LN(G4/G3) -> -0.00043407488 | J4: =F4 -> 02/03/2023 16:00:00 | K4: ='CVX DATA'!F5 -> 162.56 | L4: =LN(K4/K3) -> 0.0031422348 | N4: =J4 -> 02/03/2023 16:00:00 | O4: ='WDC DATA'!F5 -> 29.01 | P4: =LN(O4/O3) -> 0.006918049 | R4: =N4 -> 02/03/2023 16:00:00 | S4: ='MA DATA'!F5 -> 355.57 | T4: =LN(S4/S3) -> 0.0058386503 | W4: =R4 -> 02/03/2023 16:00:00 | X4: ='CEG DATA'!F5 -> 76.18 | Y4: =LN(X4/X3) -> 0.024315288
B5: ='CEG DATA'!B6 -> 03/03/2023 16:00:00 | C5: ='AAPL DATA'!F6 -> 151.03 | D5: =LN(C5/C4) -> 0.034488499 | F5: =B5 -> 03/03/2023 16:00:00 | G5: ='AMZN DATA'!F5 -> 94.9 | H5: =LN(G5/G4) -> 0.029623082 | J5: =F5 -> 03/03/2023 16:00:00 | K5: ='CVX DATA'!F6 -> 164.96 | L5: =LN(K5/K4) -> 0.014655856 | N5: =J5 -> 03/03/2023 16:00:00 | O5: ='WDC DATA'!F6 -> 29.17 | P5: =LN(O5/O4) -> 0.0055001857 | R5: =N5 -> 03/03/2023 16:00:00 | S5: ='MA DATA'!F6 -> 361.5 | T5: =LN(S5/S4) -> 0.016539906 | W5: =R5 -> 03/03/2023 16:00:00 | X5: ='CEG DATA'!F6 -> 78.98 | Y5: =LN(X5/X4) -> 0.036095695
B6: ='CEG DATA'!B7 -> 06/03/2023 16:00:00 | C6: ='AAPL DATA'!F7 -> 153.83 | D6: =LN(C6/C5) -> 0.018369604 | F6: =B6 -> 06/03/2023 16:00:00 | G6: ='AMZN DATA'!F6 -> 93.75 | H6: =LN(G6/G5) -> -0.012192041 | J6: =F6 -> 06/03/2023 16:00:00 | K6: ='CVX DATA'!F7 -> 166.17 | L6: =LN(K6/K5) -> 0.0073083404 | N6: =J6 -> 06/03/2023 16:00:00 | O6: ='WDC DATA'!F7 -> 28.56 | P6: =LN(O6/O5) -> -0.021133646 | R6: =N6 -> 06/03/2023 16:00:00 | S6: ='MA DATA'!F7 -> 366.93 | T6: =LN(S6/S5) -> 0.014909053 | W6: =R6 -> 06/03/2023 16:00:00 | X6: ='CEG DATA'!F7 -> 78.8 | Y6: =LN(X6/X5) -> -0.002281659
B7: ='CEG DATA'!B8 -> 07/03/2023 16:00:00 | C7: ='AAPL DATA'!F8 -> 151.6 | D7: =LN(C7/C6) -> -0.014602623 | F7: =B7 -> 07/03/2023 16:00:00 | G7: ='AMZN DATA'!F7 -> 93.55 | H7: =LN(G7/G6) -> -0.0021356121 | J7: =F7 -> 07/03/2023 16:00:00 | K7: ='CVX DATA'!F8 -> 164.03 | L7: =LN(K7/K6) -> -0.012962023 | N7: =J7 -> 07/03/2023 16:00:00 | O7: ='WDC DATA'!F8 -> 28.2 | P7: =LN(O7/O6) -> -0.01268516 | R7: =N7 -> 07/03/2023 16:00:00 | S7: ='MA DATA'!F8 -> 359.94 | T7: =LN(S7/S6) -> -0.019233743 | W7: =R7 -> 07/03/2023 16:00:00 | X7: ='CEG DATA'!F8 -> 77.9 | Y7: =LN(X7/X6) -> -0.011487044
B8: ='CEG DATA'!B9 -> 08/03/2023 16:00:00 | C8: ='AAPL DATA'!F9 -> 152.87 | D8: =LN(C8/C7) -> 0.0083424138 | F8: =B8 -> 08/03/2023 16:00:00 | G8: ='AMZN DATA'!F8 -> 93.92 | H8: =LN(G8/G7) -> 0.0039473034 | J8: =F8 -> 08/03/2023 16:00:00 | K8: ='CVX DATA'!F9 -> 162.99 | L8: =LN(K8/K7) -> -0.0063604887 | N8: =J8 -> 08/03/2023 16:00:00 | O8: ='WDC DATA'!F9 -> 28.65 | P8: =LN(O8/O7) -> 0.015831465 | R8: =N8 -> 08/03/2023 16:00:00 | S8: ='MA DATA'!F9 -> 359.03 | T8: =LN(S8/S7) -> -0.0025314004 | W8: =R8 -> 08/03/2023 16:00:00 | X8: ='CEG DATA'!F9 -> 78.07 | Y8: =LN(X8/X7) -> 0.0021799073
B9: ='CEG DATA'!B10 -> 09/03/2023 16:00:00 | C9: ='AAPL DATA'!F10 -> 150.59 | D9: =LN(C9/C8) -> -0.015026975 | F9: =B9 -> 09/03/2023 16:00:00 | G9: ='AMZN DATA'!F9 -> 92.25 | H9: =LN(G9/G8) -> -0.017941073 | J9: =F9 -> 09/03/2023 16:00:00 | K9: ='CVX DATA'!F10 -> 160.51 | L9: =LN(K9/K8) -> -0.015332603 | N9: =J9 -> 09/03/2023 16:00:00 | O9: ='WDC DATA'!F10 -> 28.01 | P9: =LN(O9/O8) -> -0.022591854 | R9: =N9 -> 09/03/2023 16:00:00 | S9: ='MA DATA'!F10 -> 354.44 | T9: =LN(S9/S8) -> -0.012866871 | W9: =R9 -> 09/03/2023 16:00:00 | X9: ='CEG DATA'!F10 -> 78.64 | Y9: =LN(X9/X8) -> 0.0072746157
B10: ='CEG DATA'!B11 -> 10/03/2023 16:00:00 | C10: ='AAPL DATA'!F11 -> 148.5 | D10: =LN(C10/C9) -> -0.013975954 | F10: =B10 -> 10/03/2023 16:00:00 | G10: ='AMZN DATA'!F10 -> 90.73 | H10: =LN(G10/G9) -> -0.01661422 | J10: =F10 -> 10/03/2023 16:00:00 | K10: ='CVX DATA'!F11 -> 159.67 | L10: =LN(K10/K9) -> -0.0052470606 | N10: =J10 -> 10/03/2023 16:00:00 | O10: ='WDC DATA'!F11 -> 27.26 | P10: =LN(O10/O9) -> -0.027141163 | R10: =N10 -> 10/03/2023 16:00:00 | S10: ='MA DATA'!F11 -> 347.11 | T10: =LN(S10/S9) -> -0.020897347 | W10: =R10 -> 10/03/2023 16:00:00 | X10: ='CEG DATA'!F11 -> 77.55 | Y10: =LN(X10/X9) -> -0.013957586
B11: ='CEG DATA'!B12 -> 13/03/2023 16:00:00 | C11: ='AAPL DATA'!F12 -> 150.47 | D11: =LN(C11/C10) -> 0.013178771 | F11: =B11 -> 13/03/2023 16:00:00 | G11: ='AMZN DATA'!F11 -> 92.43 | H11: =LN(G11/G10) -> 0.018563538 | J11: =F11 -> 13/03/2023 16:00:00 | K11: ='CVX DATA'!F12 -> 158.71 | L11: =LN(K11/K10) -> -0.0060305478 | N11: =J11 -> 13/03/2023 16:00:00 | O11: ='WDC DATA'!F12 -> 26.7 | P11: =LN(O11/O10) -> -0.020756861 | R11: =N11 -> 13/03/2023 16:00:00 | S11: ='MA DATA'!F12 -> 344.71 | T11: =LN(S11/S10) -> -0.0069382488 | W11: =R11 -> 13/03/2023 16:00:00 | X11: ='CEG DATA'!F12 -> 77.1 | Y11: =LN(X11/X10) -> -0.0058196091
B12: ='CEG DATA'!B13 -> 14/03/2023 16:00:00 | C12: ='AAPL DATA'!F13 -> 152.59 | D12: =LN(C12/C11) -> 0.013990857 | F12: =B12 -> 14/03/2023 16:00:00 | G12: ='AMZN DATA'!F12 -> 94.88 | H12: =LN(G12/G11) -> 0.026161334 | J12: =F12 -> 14/03/2023 16:00:00 | K12: ='CVX DATA'!F13 -> 160.76 | L12: =LN(K12/K11) -> 0.012833932 | N12: =J12 -> 14/03/2023 16:00:00 | O12: ='WDC DATA'!F13 -> 26.67 | P12: =LN(O12/O11) -> -0.0011242272 | R12: =N12 -> 14/03/2023 16:00:00 | S12: ='MA DATA'!F13 -> 352.82 | T12: =LN(S12/S11) -> 0.023254528 | W12: =R12 -> 14/03/2023 16:00:00 | X12: ='CEG DATA'!F13 -> 77.93 | Y12: =LN(X12/X11) -> 0.010707707
B13: ='CEG DATA'!B14 -> 15/03/2023 16:00:00 | C13: ='AAPL DATA'!F14 -> 152.99 | D13: =LN(C13/C12) -> 0.0026179739 | F13: =B13 -> 15/03/2023 16:00:00 | G13: ='AMZN DATA'!F13 -> 96.2 | H13: =LN(G13/G12) -> 0.013816422 | J13: =F13 -> 15/03/2023 16:00:00 | K13: ='CVX DATA'!F14 -> 153.8 | L13: =LN(K13/K12) -> -0.044259513 | N13: =J13 -> 15/03/2023 16:00:00 | O13: ='WDC DATA'!F14 -> 25.99 | P13: =LN(O13/O12) -> -0.02582749 | R13: =N13 -> 15/03/2023 16:00:00 | S13: ='MA DATA'!F14 -> 348.08 | T13: =LN(S13/S12) -> -0.013525673 | W13: =R13 -> 15/03/2023 16:00:00 | X13: ='CEG DATA'!F14 -> 77.33 | Y13: =LN(X13/X12) -> -0.0077290092
B14: ='CEG DATA'!B15 -> 16/03/2023 16:00:00 | C14: ='AAPL DATA'!F15 -> 155.85 | D14: =LN(C14/C13) -> 0.018521446 | F14: =B14 -> 16/03/2023 16:00:00 | G14: ='AMZN DATA'!F14 -> 100.04 | H14: =LN(G14/G13) -> 0.039140748 | J14: =F14 -> 16/03/2023 16:00:00 | K14: ='CVX DATA'!F15 -> 154.29 | L14: =LN(K14/K13) -> 0.0031808914 | N14: =J14 -> 16/03/2023 16:00:00 | O14: ='WDC DATA'!F15 -> 26.71 | P14: =LN(O14/O13) -> 0.027326178 | R14: =N14 -> 16/03/2023 16:00:00 | S14: ='MA DATA'!F15 -> 348 | T14: =LN(S14/S13) -> -0.00022985864 | W14: =R14 -> 16/03/2023 16:00:00 | X14: ='CEG DATA'!F15 -> 78.43 | Y14: =LN(X14/X13) -> 0.014124529
B15: ='CEG DATA'!B16 -> 17/03/2023 16:00:00 | C15: ='AAPL DATA'!F16 -> 155 | D15: =LN(C15/C14) -> -0.0054688893 | F15: =B15 -> 17/03/2023 16:00:00 | G15: ='AMZN DATA'!F15 -> 98.95 | H15: =LN(G15/G14) -> -0.010955434 | J15: =F15 -> 17/03/2023 16:00:00 | K15: ='CVX DATA'!F16 -> 152.34 | L15: =LN(K15/K14) -> -0.012719084 | N15: =J15 -> 17/03/2023 16:00:00 | O15: ='WDC DATA'!F16 -> 26.52 | P15: =LN(O15/O14) -> -0.0071388618 | R15: =N15 -> 17/03/2023 16:00:00 | S15: ='MA DATA'!F16 -> 349.66 | T15: =LN(S15/S14) -> 0.004758774 | W15: =R15 -> 17/03/2023 16:00:00 | X15: ='CEG DATA'!F16 -> 76.77 | Y15: =LN(X15/X14) -> -0.021392568
... B504: ='CEG DATA'!B505 -> 28/02/2025 16:00:00 | C504: ='AAPL DATA'!F505 -> 241.84 | D504: =LN(C504/C503) -> 0.018951187 | F504: =B504 -> 28/02/2025 16:00:00 | G504: ='AMZN DATA'!F504 -> 212.28 | H504: =LN(G504/G503) -> 0.0168167 | J504: =F504 -> 28/02/2025 16:00:00 | K504: ='CVX DATA'!F505 -> 158.62 | L504: =LN(K504/K503) -> 0.012369722 | N504: =J504 -> 28/02/2025 16:00:00 | O504: ='WDC DATA'!F505 -> 48.93 | P504: =LN(O504/O503) -> 0.015031684 | R504: =N504 -> 28/02/2025 16:00:00 | S504: ='MA DATA'!F505 -> 576.31 | T504: =LN(S504/S503) -> 0.020138614 | W504: =R504 -> 28/02/2025 16:00:00 | X504: ='CEG DATA'!F505 -> 250.55 | Y504: =LN(X504/X503) -> 0.0032381247
A505: - | B505: - | C505: - | D505: - | E505: - | F505: - | G505: - | H505: - | I505: - | J505: - | K505: - | L505: - | M505: - | N505: - | O505: - | P505: - | Q505: - | R505: - | S505: - | T505: - | U505: - | V505: - | W505: - | X505: - | Y505: - | AA505: - | AB505: - | AC505: - | AD505: - | AE505: - | AF505: - | AG505: - | AH505: - | AI505: - | AJ505: - | AK505: - | AL505: - | AM505: -

Sheet Correlation Matrix
B3: Date | C3: APPL | D3: AMZN | E3: CVX | F3: WDC | G3: MA | H3: CEG
B4: ='CEG DATA'!B4 -> 01/03/2023 16:00:00 | C4: ='% Change over timeframe'!D3 -> -0.013126599 | D4: ='% Change over timeframe'!H3 -> -0.022103904 | E4: ='% Change over timeframe'!L3 -> 0.0079301574 | F4: ='% Change over timeframe'!P3 -> -0.0096719234 | G4: ='% Change over timeframe'!T3 -> -0.0050508721 | H4: ='% Change over timeframe'!Y3 -> -0.0072366974 | I4: 1 | K4: Closing Price Correlation Mar 2023-Mar 2025
B5: ='CEG DATA'!B5 -> 02/03/2023 16:00:00 | C5: ='% Change over timeframe'!D4 -> 0.0041206019 | D5: ='% Change over timeframe'!H4 -> -0.00043407488 | E5: ='% Change over timeframe'!L4 -> 0.0031422348 | F5: ='% Change over timeframe'!P4 -> 0.006918049 | G5: ='% Change over timeframe'!T4 -> 0.0058386503 | H5: ='% Change over timeframe'!Y4 -> 0.024315288 | I5: =I4+1 -> 2
B6: ='CEG DATA'!B6 -> 03/03/2023 16:00:00 | C6: ='% Change over timeframe'!D5 -> 0.034488499 | D6: ='% Change over timeframe'!H5 -> 0.029623082 | E6: ='% Change over timeframe'!L5 -> 0.014655856 | F6: ='% Change over timeframe'!P5 -> 0.0055001857 | G6: ='% Change over timeframe'!T5 -> 0.016539906 | H6: ='% Change over timeframe'!Y5 -> 0.036095695 | I6: =I5+1 -> 3
B7: ='CEG DATA'!B7 -> 06/03/2023 16:00:00 | C7: ='% Change over timeframe'!D6 -> 0.018369604 | D7: ='% Change over timeframe'!H6 -> -0.012192041 | E7: ='% Change over timeframe'!L6 -> 0.0073083404 | F7: ='% Change over timeframe'!P6 -> -0.021133646 | G7: ='% Change over timeframe'!T6 -> 0.014909053 | H7: ='% Change over timeframe'!Y6 -> -0.002281659 | I7: =I6+1 -> 4
B8: ='CEG DATA'!B8 -> 07/03/2023 16:00:00 | C8: ='% Change over timeframe'!D7 -> -0.014602623 | D8: ='% Change over timeframe'!H7 -> -0.0021356121 | E8: ='% Change over timeframe'!L7 -> -0.012962023 | F8: ='% Change over timeframe'!P7 -> -0.01268516 | G8: ='% Change over timeframe'!T7 -> -0.019233743 | H8: ='% Change over timeframe'!Y7 -> -0.011487044 | I8: =I7+1 -> 5
B9: ='CEG DATA'!B9 -> 08/03/2023 16:00:00 | C9: ='% Change over timeframe'!D8 -> 0.0083424138 | D9: ='% Change over timeframe'!H8 -> 0.0039473034 | E9: ='% Change over timeframe'!L8 -> -0.0063604887 | F9: ='% Change over timeframe'!P8 -> 0.015831465 | G9: ='% Change over timeframe'!T8 -> -0.0025314004 | H9: ='% Change over timeframe'!Y8 -> 0.0021799073 | I9: =I8+1 -> 6
B10: ='CEG DATA'!B10 -> 09/03/2023 16:00:00 | C10: ='% Change over timeframe'!D9 -> -0.015026975 | D10: ='% Change over timeframe'!H9 -> -0.017941073 | E10: ='% Change over timeframe'!L9 -> -0.015332603 | F10: ='% Change over timeframe'!P9 -> -0.022591854 | G10: ='% Change over timeframe'!T9 -> -0.012866871 | H10: ='% Change over timeframe'!Y9 -> 0.0072746157 | I10: =I9+1 -> 7
B11: ='CEG DATA'!B11 -> 10/03/2023 16:00:00 | C11: ='% Change over timeframe'!D10 -> -0.013975954 | D11: ='% Change over timeframe'!H10 -> -0.01661422 | E11: ='% Change over timeframe'!L10 -> -0.0052470606 | F11: ='% Change over timeframe'!P10 -> -0.027141163 | G11: ='% Change over timeframe'!T10 -> -0.020897347 | H11: ='% Change over timeframe'!Y10 -> -0.013957586 | I11: =I10+1 -> 8
B12: ='CEG DATA'!B12 -> 13/03/2023 16:00:00 | C12: ='% Change over timeframe'!D11 -> 0.013178771 | D12: ='% Change over timeframe'!H11 -> 0.018563538 | E12: ='% Change over timeframe'!L11 -> -0.0060305478 | F12: ='% Change over timeframe'!P11 -> -0.020756861 | G12: ='% Change over timeframe'!T11 -> -0.0069382488 | H12: ='% Change over timeframe'!Y11 -> -0.0058196091 | I12: =I11+1 -> 9
B13: ='CEG DATA'!B13 -> 14/03/2023 16:00:00 | C13: ='% Change over timeframe'!D12 -> 0.013990857 | D13: ='% Change over timeframe'!H12 -> 0.026161334 | E13: ='% Change over timeframe'!L12 -> 0.012833932 | F13: ='% Change over timeframe'!P12 -> -0.0011242272 | G13: ='% Change over timeframe'!T12 -> 0.023254528 | H13: ='% Change over timeframe'!Y12 -> 0.010707707 | I13: =I12+1 -> 10
B14: ='CEG DATA'!B14 -> 15/03/2023 16:00:00 | C14: ='% Change over timeframe'!D13 -> 0.0026179739 | D14: ='% Change over timeframe'!H13 -> 0.013816422 | E14: ='% Change over timeframe'!L13 -> -0.044259513 | F14: ='% Change over timeframe'!P13 -> -0.02582749 | G14: ='% Change over timeframe'!T13 -> -0.013525673 | H14: ='% Change over timeframe'!Y13 -> -0.0077290092 | I14: =I13+1 -> 11
B15: ='CEG DATA'!B15 -> 16/03/2023 16:00:00 | C15: ='% Change over timeframe'!D14 -> 0.018521446 | D15: ='% Change over timeframe'!H14 -> 0.039140748 | E15: ='% Change over timeframe'!L14 -> 0.0031808914 | F15: ='% Change over timeframe'!P14 -> 0.027326178 | G15: ='% Change over timeframe'!T14 -> -0.00022985864 | H15: ='% Change over timeframe'!Y14 -> 0.014124529 | I15: =I14+1 -> 12
B16: ='CEG DATA'!B16 -> 17/03/2023 16:00:00 | C16: ='% Change over timeframe'!D15 -> -0.0054688893 | D16: ='% Change over timeframe'!H15 -> -0.010955434 | E16: ='% Change over timeframe'!L15 -> -0.012719084 | F16: ='% Change over timeframe'!P15 -> -0.0071388618 | G16: ='% Change over timeframe'!T15 -> 0.004758774 | H16: ='% Change over timeframe'!Y15 -> -0.021392568 | I16: =I15+1 -> 13
... B505: ='CEG DATA'!B505 -> 28/02/2025 16:00:00 | C505: ='% Change over timeframe'!D504 -> 0.018951187 | D505: ='% Change over timeframe'!H504 -> 0.0168167 | E505: ='% Change over timeframe'!L504 -> 0.012369722 | F505: ='% Change over timeframe'!P504 -> 0.015031684 | G505: ='% Change over timeframe'!T504 -> 0.020138614 | H505: ='% Change over timeframe'!Y504 -> 0.0032381247 | I505: =I504+1 -> 502
B506: - | D506: - | E506: - | F506: - | G506: - | H506: - | I506: - | J506: - | K506: - | L506: - | M506: - | N506: - | P506: - | Q506: -

Sheet EWMA
A1: Parameters
A2: λ = | B2: 0.94
B13: EWMA AAPL | H13: EWMA AMZN | N13: EWMA CVX | T13: EWMA WDC | Z13: EWMA MA | AF13: EWMA CEG | AX13: ='Correlation Matrix'!B506 -> - | AY13: - | AZ13: ='Correlation Matrix'!D506 -> - | BA13: ='Correlation Matrix'!E506 -> - | BB13: ='Correlation Matrix'!F506 -> - | BC13: ='Correlation Matrix'!G506 -> - | BD13: ='Correlation Matrix'!H506 -> - | BE13: ='Correlation Matrix'!I506 -> -
B14: Date | C14: Return | D14: VAR | E14: EWMA Value (Volatility) | H14: Date | I14: Return | J14: VAR | K14: EWMA Value (Volatility) | N14: Date | O14: Return | P14: VAR | Q14: EWMA Value (Volatility) | T14: Date | U14: ='Correlation Matrix'!F3 -> WDC | V14: VAR | W14: EWMA Value (Volatility) | Z14: Date | AA14: Return | AB14: VAR | AC14: EWMA Value (Volatility) | AF14: Date | AG14: Return | AH14: VAR | AI14: EWMA Value (Volatility) | AX14: ='Correlation Matrix'!B505 -> 28/02/2025 16:00:00 | AY14: ='Correlation Matrix'!C505 -> 0.018951187 | AZ14: ='Correlation Matrix'!D505 -> 0.0168167 | BA14: ='Correlation Matrix'!E505 -> 0.012369722 | BB14: ='Correlation Matrix'!F505 -> 0.015031684 | BC14: ='Correlation Matrix'!G505 -> 0.020138614 | BD14: ='Correlation Matrix'!H505 -> 0.0032381247 | BE14: ='Correlation Matrix'!I505 -> 502
B15: ='Correlation Matrix'!B4 -> 01/03/2023 16:00:00 | C15: ='Correlation Matrix'!C4 -> -0.013126599 | E15: =E517 -> 0.015896517 | H15: =B15 -> 01/03/2023 16:00:00 | I15: ='Correlation Matrix'!D4 -> -0.022103904 | J15: =VAR(I15:I516) -> 0.00033304773 | K15: =SQRT(J517) -> 0.016727698 | N15: =H15 -> 01/03/2023 16:00:00 | O15: ='Correlation Matrix'!E4 -> 0.0079301574 | P15: =VAR(O15:O516) -> 0.00017081741 | Q15: =SQRT(P517) -> 0.012346752 | T15: =N15 -> 01/03/2023 16:00:00 | U15: ='Correlation Matrix'!F4 -> -0.0096719234 | V15: =VAR(U15:U516) -> 0.00057531728 | W15: =SQRT(V517) -> 0.028193156 | Z15: =T15 -> 01/03/2023 16:00:00 | AA15: ='Correlation Matrix'!G4 -> -0.0050508721 | AB15: =VAR(AA15:AA516) -> 0.00010757248 | AC15: =SQRT(AB517) -> 0.010605493 | AF15: =Z15 -> 01/03/2023 16:00:00 | AG15: ='Correlation Matrix'!H4 -> -0.0072366974 | AH15: =VAR(AG15:AG516) -> 0.00095877323 | AI15: =SQRT(AH517) -> 0.051277197 | AX15: ='Correlation Matrix'!B504 -> 27/02/2025 16:00:00 | AY15: ='Correlation Matrix'!C504 -> -0.012812636 | AZ15: ='Correlation Matrix'!D504 -> -0.026520735 | BA15: ='Correlation Matrix'!E504 -> 0.0098137473 | BB15: ='Correlation Matrix'!F504 -> -0.039858875 | BC15: ='Correlation Matrix'!G504 -> 0.0063050232 | BD15: ='Correlation Matrix'!H504 -> -0.078519966 | BE15: ='Correlation Matrix'!I504 -> 501
B16: ='Correlation Matrix'!B5 -> 02/03/2023 16:00:00 | C16: ='Correlation Matrix'!C5 -> 0.0041206019 | D16: =VAR(C16:C516) -> 0.00018658142 | H16: =B16 -> 02/03/2023 16:00:00 | I16: ='Correlation Matrix'!D5 -> -0.00043407488 | J16: =$B$2*J15+(1-$B$2)*I15^2 -> 0.00034237982 | N16: =H16 -> 02/03/2023 16:00:00 | O16: ='Correlation Matrix'!E5 -> 0.0031422348 | P16: =$B$2*P15+(1-$B$2)*O15^2 -> 0.00016434161 | T16: =N16 -> 02/03/2023 16:00:00 | U16: ='Correlation Matrix'!F5 -> 0.006918049 | V16: =$B$2*V15+(1-$B$2)*U15^2 -> 0.00054641101 | Z16: =T16 -> 02/03/2023 16:00:00 | AA16: ='Correlation Matrix'!G5 -> 0.0058386503 | AB16: =$B$2*AB15+(1-$B$2)*AA15^2 -> 0.00010264881 | AF16: =Z16 -> 02/03/2023 16:00:00 | AG16: ='Correlation Matrix'!H5 -> 0.024315288 | AH16: =$B$2*AH15+(1-$B$2)*AG15^2 -> 0.00090438902 | AX16: ='Correlation Matrix'!B503 -> 26/02/2025 16:00:00 | AY16: ='Correlation Matrix'!C503 -> -0.027412467 | AZ16: ='Correlation Matrix'!D503 -> 0.0072574356 | BA16: ='Correlation Matrix'!E503 -> -0.0082167621 | BB16: ='Correlation Matrix'!F503 -> 0.021970046 | BC16: ='Correlation Matrix'!G503 -> -0.0049053684 | BD16: ='Correlation Matrix'!H503 -> 0.021817686 | BE16: ='Correlation Matrix'!I503 -> 500
B17: ='Correlation Matrix'!B6 -> 03/03/2023 16:00:00 | C17: ='Correlation Matrix'!C6 -> 0.034488499 | D17: =$B$2*D16+(1-$B$2)*C16^2 -> 0.0001764053 | H17: =B17 -> 03/03/2023 16:00:00 | I17: ='Correlation Matrix'!D6 -> 0.029623082 | J17: =$B$2*J16+(1-$B$2)*I16^2 -> 0.00032184833 | N17: =H17 -> 03/03/2023 16:00:00 | O17: ='Correlation Matrix'!E6 -> 0.014655856 | P17: =$B$2*P16+(1-$B$2)*O16^2 -> 0.00015507353 | T17: =N17 -> 03/03/2023 16:00:00 | U17: ='Correlation Matrix'!F6 -> 0.0055001857 | V17: =$B$2*V16+(1-$B$2)*U16^2 -> 0.00051649792 | Z17: =T17 -> 03/03/2023 16:00:00 | AA17: ='Correlation Matrix'!G6 -> 0.016539906 | AB17: =$B$2*AB16+(1-$B$2)*AA16^2 -> 9.8535272e-05 | AF17: =Z17 -> 03/03/2023 16:00:00 | AG17: ='Correlation Matrix'!H6 -> 0.036095695 | AH17: =$B$2*AH16+(1-$B$2)*AG16^2 -> 0.00088559968 | AX17: ='Correlation Matrix'!B502 -> 25/02/2025 16:00:00 | AY17: ='Correlation Matrix'!C502 -> -0.00024284616 | AZ17: ='Correlation Matrix'!D502 -> 0.00042302179 | BA17: ='Correlation Matrix'!E502 -> -0.0093538909 | BB17: ='Correlation Matrix'!F502 -> 0.001019472 | BC17: ='Correlation Matrix'!G502 -> 0.0089579684 | BD17: ='Correlation Matrix'!H502 -> -0.012819002 | BE17: ='Correlation Matrix'!I502 -> 499
B18: ='Correlation Matrix'!B7 -> 06/03/2023 16:00:00 | C18: ='Correlation Matrix'!C7 -> 0.018369604 | D18: =$B$2*D17+(1-$B$2)*C17^2 -> 0.00023718837 | H18: =B18 -> 06/03/2023 16:00:00 | I18: ='Correlation Matrix'!D7 -> -0.012192041 | J18: =$B$2*J17+(1-$B$2)*I17^2 -> 0.00035518905 | N18: =H18 -> 06/03/2023 16:00:00 | O18: ='Correlation Matrix'!E7 -> 0.0073083404 | P18: =$B$2*P17+(1-$B$2)*O17^2 -> 0.00015865676 | T18: =N18 -> 06/03/2023 16:00:00 | U18: ='Correlation Matrix'!F7 -> -0.021133646 | V18: =$B$2*V17+(1-$B$2)*U17^2 -> 0.00048732316 | Z18: =T18 -> 06/03/2023 16:00:00 | AA18: ='Correlation Matrix'!G7 -> 0.014909053 | AB18: =$B$2*AB17+(1-$B$2)*AA17^2 -> 0.00010903727 | AF18: =Z18 -> 06/03/2023 16:00:00 | AG18: ='Correlation Matrix'!H7 -> -0.002281659 | AH18: =$B$2*AH17+(1-$B$2)*AG17^2 -> 0.00091063765 | AX18: ='Correlation Matrix'!B501 -> 24/02/2025 16:00:00 | AY18: ='Correlation Matrix'!C501 -> 0.0062925205 | AZ18: ='Correlation Matrix'!D501 -> -0.018030259 | BA18: ='Correlation Matrix'!E501 -> 0.0061624667 | BB18: ='Correlation Matrix'!F501 -> -0.05766828 | BC18: ='Correlation Matrix'!G501 -> 0.0026690328 | BD18: ='Correlation Matrix'!H501 -> -0.060580677 | BE18: ='Correlation Matrix'!I501 -> 498
B19: ='Correlation Matrix'!B8 -> 07/03/2023 16:00:00 | C19: ='Correlation Matrix'!C8 -> -0.014602623 | D19: =$B$2*D18+(1-$B$2)*C18^2 -> 0.00024320361 | H19: =B19 -> 07/03/2023 16:00:00 | I19: ='Correlation Matrix'!D8 -> -0.0021356121 | J19: =$B$2*J18+(1-$B$2)*I18^2 -> 0.00034279646 | N19: =H19 -> 07/03/2023 16:00:00 | O19: ='Correlation Matrix'!E8 -> -0.012962023 | P19: =$B$2*P18+(1-$B$2)*O18^2 -> 0.00015234207 | T19: =N19 -> 07/03/2023 16:00:00 | U19: ='Correlation Matrix'!F8 -> -0.01268516 | V19: =$B$2*V18+(1-$B$2)*U18^2 -> 0.00048488163 | Z19: =T19 -> 07/03/2023 16:00:00 | AA19: ='Correlation Matrix'!G8 -> -0.019233743 | AB19: =$B$2*AB18+(1-$B$2)*AA18^2 -> 0.00011583182 | AF19: =Z19 -> 07/03/2023 16:00:00 | AG19: ='Correlation Matrix'!H8 -> -0.011487044 | AH19: =$B$2*AH18+(1-$B$2)*AG18^2 -> 0.00085631175 | AX19: ='Correlation Matrix'!B500 -> 21/02/2025 16:00:00 | AY19: ='Correlation Matrix'!C500 -> -0.0011396476 | AZ19: ='Correlation Matrix'!D500 -> -0.028673516 | BA19: ='Correlation Matrix'!E500 -> -0.011846453 | BB19: ='Correlation Matrix'!F500 -> -0.037048274 | BC19: ='Correlation Matrix'!G500 -> -0.0102964 | BD19: ='Correlation Matrix'!H500 -> -0.084177242 | BE19: ='Correlation Matrix'!I500 -> 497
B20: ='Correlation Matrix'!B9 -> 08/03/2023 16:00:00 | C20: ='Correlation Matrix'!C9 -> 0.0083424138 | D20: =$B$2*D19+(1-$B$2)*C19^2 -> 0.00024140559 | H20: =B20 -> 08/03/2023 16:00:00 | I20: ='Correlation Matrix'!D9 -> 0.0039473034 | J20: =$B$2*J19+(1-$B$2)*I19^2 -> 0.00032250233 | N20: =H20 -> 08/03/2023 16:00:00 | O20: ='Correlation Matrix'!E9 -> -0.0063604887 | P20: =$B$2*P19+(1-$B$2)*O19^2 -> 0.00015328239 | T20: =N20 -> 08/03/2023 16:00:00 | U20: ='Correlation Matrix'!F9 -> 0.015831465 | V20: =$B$2*V19+(1-$B$2)*U19^2 -> 0.00046544353 | Z20: =T20 -> 08/03/2023 16:00:00 | AA20: ='Correlation Matrix'!G9 -> -0.0025314004 | AB20: =$B$2*AB19+(1-$B$2)*AA19^2 -> 0.00013107812 | AF20: =Z20 -> 08/03/2023 16:00:00 | AG20: ='Correlation Matrix'!H9 -> 0.0021799073 | AH20: =$B$2*AH19+(1-$B$2)*AG19^2 -> 0.00081285017 | AX20: ='Correlation Matrix'!B499 -> 20/02/2025 16:00:00 | AY20: ='Correlation Matrix'!C499 -> 0.0039127827 | AZ20: ='Correlation Matrix'!D499 -> -0.016685222 | BA20: ='Correlation Matrix'!E499 -> 0.0098728731 | BB20: ='Correlation Matrix'!F499 -> -0.0027795811 | BC20: ='Correlation Matrix'!G499 -> -0.009224473 | BD20: ='Correlation Matrix'!H499 -> -0.038826598 | BE20: ='Correlation Matrix'!I499 -> 496
B21: ='Correlation Matrix'!B10 -> 09/03/2023 16:00:00 | C21: ='Correlation Matrix'!C10 -> -0.015026975 | D21: =$B$2*D20+(1-$B$2)*C20^2 -> 0.00023109701 | H21: =B21 -> 09/03/2023 16:00:00 | I21: ='Correlation Matrix'!D10 -> -0.017941073 | J21: =$B$2*J20+(1-$B$2)*I20^2 -> 0.00030408706 | N21: =H21 -> 09/03/2023 16:00:00 | O21: ='Correlation Matrix'!E10 -> -0.015332603 | P21: =$B$2*P20+(1-$B$2)*O20^2 -> 0.00014651279 | T21: =N21 -> 09/03/2023 16:00:00 | U21: ='Correlation Matrix'!F10 -> -0.022591854 | V21: =$B$2*V20+(1-$B$2)*U20^2 -> 0.00045255504 | Z21: =T21 -> 09/03/2023 16:00:00 | AA21: ='Correlation Matrix'!G10 -> -0.012866871 | AB21: =$B$2*AB20+(1-$B$2)*AA20^2 -> 0.00012359792 | AF21: =Z21 -> 09/03/2023 16:00:00 | AG21: ='Correlation Matrix'!H10 -> 0.0072746157 | AH21: =$B$2*AH20+(1-$B$2)*AG20^2 -> 0.00076436428 | AX21: ='Correlation Matrix'!B498 -> 19/02/2025 16:00:00 | AY21: ='Correlation Matrix'!C498 -> 0.0016348555 | AZ21: ='Correlation Matrix'!D498 -> -8.8245676e-05 | BA21: ='Correlation Matrix'!E498 -> 0.0068285788 | BB21: ='Correlation Matrix'!F498 -> -0.0075583363 | BC21: ='Correlation Matrix'!G498 -> -0.00019347293 | BD21: ='Correlation Matrix'!H498 -> -0.012143459 | BE21: ='Correlation Matrix'!I498 -> 495
B22: ='Correlation Matrix'!B11 -> 10/03/2023 16:00:00 | C22: ='Correlation Matrix'!C11 -> -0.013975954 | D22: =$B$2*D21+(1-$B$2)*C21^2 -> 0.00023077979 | H22: =B22 -> 10/03/2023 16:00:00 | I22: ='Correlation Matrix'!D11 -> -0.01661422 | J22: =$B$2*J21+(1-$B$2)*I21^2 -> 0.00030515476 | N22: =H22 -> 10/03/2023 16:00:00 | O22: ='Correlation Matrix'!E11 -> -0.0052470606 | P22: =$B$2*P21+(1-$B$2)*O21^2 -> 0.00015182735 | T22: =N22 -> 10/03/2023 16:00:00 | U22: ='Correlation Matrix'!F11 -> -0.027141163 | V22: =$B$2*V21+(1-$B$2)*U21^2 -> 0.00045602525 | Z22: =T22 -> 10/03/2023 16:00:00 | AA22: ='Correlation Matrix'!G11 -> -0.020897347 | AB22: =$B$2*AB21+(1-$B$2)*AA21^2 -> 0.00012611542 | AF22: =Z22 -> 10/03/2023 16:00:00 | AG22: ='Correlation Matrix'!H11 -> -0.013957586 | AH22: =$B$2*AH21+(1-$B$2)*AG21^2 -> 0.00072167763 | AX22: ='Correlation Matrix'!B497 -> 18/02/2025 16:00:00 | AY22: ='Correlation Matrix'!C497 -> -0.00053162125 | AZ22: ='Correlation Matrix'!D497 -> -0.008916669 | BA22: ='Correlation Matrix'!E497 -> 0.0052648597 | BB22: ='Correlation Matrix'!F497 -> 0.05201851 | BC22: ='Correlation Matrix'!G497 -> 0.006793924 | BD22: ='Correlation Matrix'!H497 -> 0.025821936 | BE22: ='Correlation Matrix'!I497 -> 494
B23: ='Correlation Matrix'!B12 -> 13/03/2023 16:00:00 | C23: ='Correlation Matrix'!C12 -> 0.013178771 | D23: =$B$2*D22+(1-$B$2)*C22^2 -> 0.00022865264 | H23: =B23 -> 13/03/2023 16:00:00 | I23: ='Correlation Matrix'!D12 -> 0.018563538 | J23: =$B$2*J22+(1-$B$2)*I22^2 -> 0.00030340741 | N23: =H23 -> 13/03/2023 16:00:00 | O23: ='Correlation Matrix'!E12 -> -0.0060305478 | P23: =$B$2*P22+(1-$B$2)*O22^2 -> 0.00014436961 | T23: =N23 -> 13/03/2023 16:00:00 | U23: ='Correlation Matrix'!F12 -> -0.020756861 | V23: =$B$2*V22+(1-$B$2)*U22^2 -> 0.0004728623 | Z23: =T23 -> 13/03/2023 16:00:00 | AA23: ='Correlation Matrix'!G12 -> -0.0069382488 | AB23: =$B$2*AB22+(1-$B$2)*AA22^2 -> 0.00014475044 | AF23: =Z23 -> 13/03/2023 16:00:00 | AG23: ='Correlation Matrix'!H12 -> -0.0058196091 | AH23: =$B$2*AH22+(1-$B$2)*AG22^2 -> 0.00069006582 | AX23: ='Correlation Matrix'!B496 -> 14/02/2025 16:00:00 | AY23: ='Correlation Matrix'!C496 -> 0.012630534 | AZ23: ='Correlation Matrix'!D496 -> -0.0073630656 | BA23: ='Correlation Matrix'!E496 -> -0.0034702175 | BB23: ='Correlation Matrix'!F496 -> 0.012067099 | BC23: ='Correlation Matrix'!G496 -> -0.0027407693 | BD23: ='Correlation Matrix'!H496 -> 0.018480464 | BE23: ='Correlation Matrix'!I496 -> 493
B24: ='Correlation Matrix'!B13 -> 14/03/2023 16:00:00 | C24: ='Correlation Matrix'!C13 -> 0.013990857 | D24: =$B$2*D23+(1-$B$2)*C23^2 -> 0.00022535428 | H24: =B24 -> 14/03/2023 16:00:00 | I24: ='Correlation Matrix'!D13 -> 0.026161334 | J24: =$B$2*J23+(1-$B$2)*I23^2 -> 0.00030587927 | N24: =H24 -> 14/03/2023 16:00:00 | O24: ='Correlation Matrix'!E13 -> 0.012833932 | P24: =$B$2*P23+(1-$B$2)*O23^2 -> 0.00013788948 | T24: =N24 -> 14/03/2023 16:00:00 | U24: ='Correlation Matrix'!F13 -> -0.0011242272 | V24: =$B$2*V23+(1-$B$2)*U23^2 -> 0.0004703414 | Z24: =T24 -> 14/03/2023 16:00:00 | AA24: ='Correlation Matrix'!G13 -> 0.023254528 | AB24: =$B$2*AB23+(1-$B$2)*AA23^2 -> 0.00013895377 | AF24: =Z24 -> 14/03/2023 16:00:00 | AG24: ='Correlation Matrix'!H13 -> 0.010707707 | AH24: =$B$2*AH23+(1-$B$2)*AG23^2 -> 0.00065069394 | AX24: ='Correlation Matrix'!B495 -> 13/02/2025 16:00:00 | AY24: ='Correlation Matrix'!C495 -> 0.019482222 | AZ24: ='Correlation Matrix'!D495 -> 0.006270432 | BA24: ='Correlation Matrix'!E495 -> 0.006306733 | BB24: ='Correlation Matrix'!F495 -> 0.0043171182 | BC24: ='Correlation Matrix'!G495 -> 0.0030241156 | BD24: ='Correlation Matrix'!H495 -> -0.0073886053 | BE24: ='Correlation Matrix'!I495 -> 492
B25: ='Correlation Matrix'!B14 -> 15/03/2023 16:00:00 | C25: ='Correlation Matrix'!C14 -> 0.0026179739 | D25: =$B$2*D24+(1-$B$2)*C24^2 -> 0.00022357767 | H25: =B25 -> 15/03/2023 16:00:00 | I25: ='Correlation Matrix'!D14 -> 0.013816422 | J25: =$B$2*J24+(1-$B$2)*I24^2 -> 0.00032859143 | N25: =H25 -> 15/03/2023 16:00:00 | O25: ='Correlation Matrix'!E14 -> -0.044259513 | P25: =$B$2*P24+(1-$B$2)*O24^2 -> 0.0001394987 | T25: =N25 -> 15/03/2023 16:00:00 | U25: ='Correlation Matrix'!F14 -> -0.02582749 | V25: =$B$2*V24+(1-$B$2)*U24^2 -> 0.00044219674 | Z25: =T25 -> 15/03/2023 16:00:00 | AA25: ='Correlation Matrix'!G14 -> -0.013525673 | AB25: =$B$2*AB24+(1-$B$2)*AA24^2 -> 0.00016306293 | AF25: =Z25 -> 15/03/2023 16:00:00 | AG25: ='Correlation Matrix'!H14 -> -0.0077290092 | AH25: =$B$2*AH24+(1-$B$2)*AG24^2 -> 0.00061853161 | AX25: ='Correlation Matrix'!B494 -> 12/02/2025 16:00:00 | AY25: ='Correlation Matrix'!C494 -> 0.018105247 | AZ25: ='Correlation Matrix'!D494 -> -0.0165916 | BA25: ='Correlation Matrix'!E494 -> -0.016264686 | BB25: ='Correlation Matrix'!F494 -> -0.024092869 | BC25: ='Correlation Matrix'!G494 -> -0.00017710086 | BD25: ='Correlation Matrix'!H494 -> 0.00070132937 | BE25: ='Correlation Matrix'!I494 -> 491
B26: ='Correlation Matrix'!B15 -> 16/03/2023 16:00:00 | C26: ='Correlation Matrix'!C15 -> 0.018521446 | D26: =$B$2*D25+(1-$B$2)*C25^2 -> 0.00021057423 | H26: =B26 -> 16/03/2023 16:00:00 | I26: ='Correlation Matrix'!D15 -> 0.039140748 | J26: =$B$2*J25+(1-$B$2)*I25^2 -> 0.00032032956 | N26: =H26 -> 16/03/2023 16:00:00 | O26: ='Correlation Matrix'!E15 -> 0.0031808914 | P26: =$B$2*P25+(1-$B$2)*O25^2 -> 0.00024866305 | T26: =N26 -> 16/03/2023 16:00:00 | U26: ='Correlation Matrix'!F15 -> 0.027326178 | V26: =$B$2*V25+(1-$B$2)*U25^2 -> 0.00045568849 | Z26: =T26 -> 16/03/2023 16:00:00 | AA26: ='Correlation Matrix'!G15 -> -0.00022985864 | AB26: =$B$2*AB25+(1-$B$2)*AA25^2 -> 0.00016425579 | AF26: =Z26 -> 16/03/2023 16:00:00 | AG26: ='Correlation Matrix'!H15 -> 0.014124529 | AH26: =$B$2*AH25+(1-$B$2)*AG25^2 -> 0.00058500397 | AX26: ='Correlation Matrix'!B493 -> 11/02/2025 16:00:00 | AY26: ='Correlation Matrix'!C493 -> 0.021596859 | AZ26: ='Correlation Matrix'!D493 -> -0.0016312517 | BA26: ='Correlation Matrix'!E493 -> 0.010663873 | BB26: ='Correlation Matrix'!F493 -> -0.0019179139 | BC26: ='Correlation Matrix'!G493 -> -0.0013979953 | BD26: ='Correlation Matrix'!H493 -> -0.025968945 | BE26: ='Correlation Matrix'!I493 -> 490
B27: ='Correlation Matrix'!B16 -> 17/03/2023 16:00:00 | C27: ='Correlation Matrix'!C16 -> -0.0054688893 | D27: =$B$2*D26+(1-$B$2)*C26^2 -> 0.00021852242 | H27: =B27 -> 17/03/2023 16:00:00 | I27: ='Correlation Matrix'!D16 -> -0.010955434 | J27: =$B$2*J26+(1-$B$2)*I26^2 -> 0.00039302968 | N27: =H27 -> 17/03/2023 16:00:00 | O27: ='Correlation Matrix'!E16 -> -0.012719084 | P27: =$B$2*P26+(1-$B$2)*O26^2 -> 0.00023435035 | T27: =N27 -> 17/03/2023 16:00:00 | U27: ='Correlation Matrix'!F16 -> -0.0071388618 | V27: =$B$2*V26+(1-$B$2)*U26^2 -> 0.00047315039 | Z27: =T27 -> 17/03/2023 16:00:00 | AA27: ='Correlation Matrix'!G16 -> 0.004758774 | AB27: =$B$2*AB26+(1-$B$2)*AA26^2 -> 0.00015440361 | AF27: =Z27 -> 17/03/2023 16:00:00 | AG27: ='Correlation Matrix'!H16 -> -0.021392568 | AH27: =$B$2*AH26+(1-$B$2)*AG26^2 -> 0.00056187387 | AX27: ='Correlation Matrix'!B492 -> 10/02/2025 16:00:00 | AY27: ='Correlation Matrix'!C492 -> 8.7858021e-05 | AZ27: ='Correlation Matrix'!D492 -> 0.017262321 | BA27: ='Correlation Matrix'!E492 -> 0.020429388 | BB27: ='Correlation Matrix'!F492 -> 0.068801282 | BC27: ='Correlation Matrix'!G492 -> 0.0048571321 | BD27: ='Correlation Matrix'!H492 -> 0.038128807 | BE27: ='Correlation Matrix'!I492 -> 489
B28: ='Correlation Matrix'!B17 -> 20/03/2023 16:00:00 | C28: ='Correlation Matrix'!C17 -> 0.015365219 | D28: =$B$2*D27+(1-$B$2)*C27^2 -> 0.0002072056 | H28: =B28 -> 20/03/2023 16:00:00 | I28: ='Correlation Matrix'!D17 -> -0.012610764 | J28: =$B$2*J27+(1-$B$2)*I27^2 -> 0.00037664919 | N28: =H28 -> 20/03/2023 16:00:00 | O28: ='Correlation Matrix'!E17 -> 0.014596897 | P28: =$B$2*P27+(1-$B$2)*O27^2 -> 0.00022999583 | T28: =N28 -> 20/03/2023 16:00:00 | U28: ='Correlation Matrix'!F17 -> 0.0033879197 | V28: =$B$2*V27+(1-$B$2)*U27^2 -> 0.00044781916 | Z28: =T28 -> 20/03/2023 16:00:00 | AA28: ='Correlation Matrix'!G17 -> -0.00097284622 | AB28: =$B$2*AB27+(1-$B$2)*AA27^2 -> 0.00014649815 | AF28: =Z28 -> 20/03/2023 16:00:00 | AG28: ='Correlation Matrix'!H17 -> 0.002991483 | AH28: =$B$2*AH27+(1-$B$2)*AG27^2 -> 0.00055561995 | AX28: ='Correlation Matrix'!B491 -> 07/02/2025 16:00:00 | AY28: ='Correlation Matrix'!C491 -> -0.02426071 | AZ28: ='Correlation Matrix'!D491 -> -0.041375191 | BA28: ='Correlation Matrix'!E491 -> 0.0047287623 | BB28: ='Correlation Matrix'!F491 -> -0.0004104248 | BC28: ='Correlation Matrix'!G491 -> -0.0078059711 | BD28: ='Correlation Matrix'!H491 -> -0.0064673081 | BE28: ='Correlation Matrix'!I491 -> 488
B29: ='Correlation Matrix'!B18 -> 21/03/2023 16:00:00 | C29: ='Correlation Matrix'!C18 -> 0.011873324 | D29: =$B$2*D28+(1-$B$2)*C28^2 -> 0.00020893866 | H29: =B29 -> 21/03/2023 16:00:00 | I29: ='Correlation Matrix'!D18 -> 0.029247748 | J29: =$B$2*J28+(1-$B$2)*I28^2 -> 0.00036359212 | N29: =H29 -> 21/03/2023 16:00:00 | O29: ='Correlation Matrix'!E18 -> 0.030140228 | P29: =$B$2*P28+(1-$B$2)*O28^2 -> 0.00022898024 | T29: =N29 -> 21/03/2023 16:00:00 | U29: ='Correlation Matrix'!F18 -> 0.0074878673 | V29: =$B$2*V28+(1-$B$2)*U28^2 -> 0.00042163869 | Z29: =T29 -> 21/03/2023 16:00:00 | AA29: ='Correlation Matrix'!G18 -> 0.01491738 | AB29: =$B$2*AB28+(1-$B$2)*AA28^2 -> 0.00013776505 | AF29: =Z29 -> 21/03/2023 16:00:00 | AG29: ='Correlation Matrix'!H18 -> -0.0062532773 | AH29: =$B$2*AH28+(1-$B$2)*AG28^2 -> 0.00052281969 | AX29: ='Correlation Matrix'!B490 -> 06/02/2025 16:00:00 | AY29: ='Correlation Matrix'!C490 -> 0.0032210296 | AZ29: ='Correlation Matrix'!D490 -> 0.011200117 | BA29: ='Correlation Matrix'!E490 -> -0.0071501502 | BB29: ='Correlation Matrix'!F490 -> -0.0036862626 | BC29: ='Correlation Matrix'!G490 -> 0.0015351364 | BD29: ='Correlation Matrix'!H490 -> -0.0064894814 | BE29: ='Correlation Matrix'!I490 -> 487
B30: ='Correlation Matrix'!B19 -> 22/03/2023 16:00:00 | C30: ='Correlation Matrix'!C19 -> -0.0091451553 | D30: =$B$2*D29+(1-$B$2)*C29^2 -> 0.00020486089 | H30: =B30 -> 22/03/2023 16:00:00 | I30: ='Correlation Matrix'!D19 -> -0.01916671 | J30: =$B$2*J29+(1-$B$2)*I29^2 -> 0.00039310244 | N30: =H30 -> 22/03/2023 16:00:00 | O30: ='Correlation Matrix'!E19 -> -0.020547365 | P30: =$B$2*P29+(1-$B$2)*O29^2 -> 0.00026974743 | T30: =N30 -> 22/03/2023 16:00:00 | U30: ='Correlation Matrix'!F19 -> -0.021871158 | V30: =$B$2*V29+(1-$B$2)*U29^2 -> 0.00039970446 | Z30: =T30 -> 22/03/2023 16:00:00 | AA30: ='Correlation Matrix'!G19 -> -0.010034098 | AB30: =$B$2*AB29+(1-$B$2)*AA29^2 -> 0.00014285084 | AF30: =Z30 -> 22/03/2023 16:00:00 | AG30: ='Correlation Matrix'!H19 -> -0.027827422 | AH30: =$B$2*AH29+(1-$B$2)*AG29^2 -> 0.00049379672 | AX30: ='Correlation Matrix'!B489 -> 05/02/2025 16:00:00 | AY30: ='Correlation Matrix'!C489 -> -0.0014185314 | AZ30: ='Correlation Matrix'!D489 -> -0.024633745 | BA30: ='Correlation Matrix'!E489 -> -0.0015022373 | BB30: ='Correlation Matrix'!F489 -> 0.014205077 | BC30: ='Correlation Matrix'!G489 -> 0.012760081 | BD30: ='Correlation Matrix'!H489 -> 0.024188486 | BE30: ='Correlation Matrix'!I489 -> 486
B31: ='Correlation Matrix'!B20 -> 23/03/2023 16:00:00 | C31: ='Correlation Matrix'!C20 -> 0.0069453493 | D31: =$B$2*D30+(1-$B$2)*C30^2 -> 0.00019758727 | H31: =B31 -> 23/03/2023 16:00:00 | I31: ='Correlation Matrix'!D20 -> 0.00010131199 | J31: =$B$2*J30+(1-$B$2)*I30^2 -> 0.00039155806 | N31: =H31 -> 23/03/2023 16:00:00 | O31: ='Correlation Matrix'!E20 -> -0.0099810868 | P31: =$B$2*P30+(1-$B$2)*O30^2 -> 0.00027889424 | T31: =N31 -> 23/03/2023 16:00:00 | U31: ='Correlation Matrix'!F20 -> 0.016260521 | V31: =$B$2*V30+(1-$B$2)*U30^2 -> 0.00040442305 | Z31: =T31 -> 23/03/2023 16:00:00 | AA31: ='Correlation Matrix'!G20 -> 0.0094698751 | AB31: =$B$2*AB30+(1-$B$2)*AA30^2 -> 0.00014032077 | AF31: =Z31 -> 23/03/2023 16:00:00 | AG31: ='Correlation Matrix'!H20 -> -0.013800787 | AH31: =$B$2*AH30+(1-$B$2)*AG30^2 -> 0.00051063084 | AX31: ='Correlation Matrix'!B488 -> 04/02/2025 16:00:00 | AY31: ='Correlation Matrix'!C488 -> 0.020790228 | AZ31: ='Correlation Matrix'!D488 -> 0.019354905 | BA31: ='Correlation Matrix'!E488 -> 0.025649211 | BB31: ='Correlation Matrix'!F488 -> -0.0094924361 | BC31: ='Correlation Matrix'!G488 -> -0.0086193613 | BD31: ='Correlation Matrix'!H488 -> 6.5291199e-05 | BE31: ='Correlation Matrix'!I488 -> 485
B32: ='Correlation Matrix'!B21 -> 24/03/2023 16:00:00 | C32: ='Correlation Matrix'!C21 -> 0.0082712421 | D32: =$B$2*D31+(1-$B$2)*C31^2 -> 0.0001886263 | H32: =B32 -> 24/03/2023 16:00:00 | I32: ='Correlation Matrix'!D21 -> -0.0058931282 | J32: =$B$2*J31+(1-$B$2)*I31^2 -> 0.00036806519 | N32: =H32 -> 24/03/2023 16:00:00 | O32: ='Correlation Matrix'!E21 -> 0.0099170109 | P32: =$B$2*P31+(1-$B$2)*O31^2 -> 0.00026813791 | T32: =N32 -> 24/03/2023 16:00:00 | U32: ='Correlation Matrix'!F21 -> -0.00037516414 | V32: =$B$2*V31+(1-$B$2)*U31^2 -> 0.00039602194 | Z32: =T32 -> 24/03/2023 16:00:00 | AA32: ='Correlation Matrix'!G21 -> -0.0077620786 | AB32: =$B$2*AB31+(1-$B$2)*AA31^2 -> 0.00013728224 | AF32: =Z32 -> 24/03/2023 16:00:00 | AG32: ='Correlation Matrix'!H21 -> 0.00054481069 | AH32: =$B$2*AH31+(1-$B$2)*AG31^2 -> 0.00049142069 | AX32: ='Correlation Matrix'!B487 -> 03/02/2025 16:00:00 | AY32: ='Correlation Matrix'!C487 -> -0.034442317 | AZ32: ='Correlation Matrix'!D487 -> -0.0010945065 | BA32: ='Correlation Matrix'!E487 -> 0.0010049242 | BB32: ='Correlation Matrix'!F487 -> -0.011029524 | BC32: ='Correlation Matrix'!G487 -> 0.015223007 | BD32: ='Correlation Matrix'!H487 -> 0.020881855 | BE32: ='Correlation Matrix'!I487 -> 484
B33: ='Correlation Matrix'!B22 -> 27/03/2023 16:00:00 | C33: ='Correlation Matrix'!C22 -> -0.012369479 | D33: =$B$2*D32+(1-$B$2)*C32^2 -> 0.00018141353 | H33: =B33 -> 27/03/2023 16:00:00 | I33: ='Correlation Matrix'!D22 -> -0.00091757156 | J33: =$B$2*J32+(1-$B$2)*I32^2 -> 0.00034806502 | N33: =H33 -> 27/03/2023 16:00:00 | O33: ='Correlation Matrix'!E22 -> 0.010136837 | P33: =$B$2*P32+(1-$B$2)*O32^2 -> 0.00025795046 | T33: =N33 -> 27/03/2023 16:00:00 | U33: ='Correlation Matrix'!F22 -> -0.0015020656 | V33: =$B$2*V32+(1-$B$2)*U32^2 -> 0.00037226907 | Z33: =T33 -> 27/03/2023 16:00:00 | AA33: ='Correlation Matrix'!G22 -> 0.0084673072 | AB33: =$B$2*AB32+(1-$B$2)*AA32^2 -> 0.0001326603 | AF33: =Z33 -> 27/03/2023 16:00:00 | AG33: ='Correlation Matrix'!H22 -> 0.024612903 | AH33: =$B$2*AH32+(1-$B$2)*AG32^2 -> 0.00046195326 | AX33: ='Correlation Matrix'!B486 -> 31/01/2025 16:00:00 | AY33: ='Correlation Matrix'!C486 -> -0.006714694 | AZ33: ='Correlation Matrix'!D486 -> 0.012872806 | BA33: ='Correlation Matrix'!E486 -> -0.046684527 | BB33: ='Correlation Matrix'!F486 -> -0.0099040729 | BC33: ='Correlation Matrix'!G486 -> -0.018869157 | BD33: ='Correlation Matrix'!H486 -> -0.028168099 | BE33: ='Correlation Matrix'!I486 -> 483
B34: ='Correlation Matrix'!B23 -> 28/03/2023 16:00:00 | C34: ='Correlation Matrix'!C23 -> -0.0039882305 | D34: =$B$2*D33+(1-$B$2)*C33^2 -> 0.00017970896 | H34: =B34 -> 28/03/2023 16:00:00 | I34: ='Correlation Matrix'!D23 -> -0.0081934092 | J34: =$B$2*J33+(1-$B$2)*I33^2 -> 0.00032723163 | N34: =H34 -> 28/03/2023 16:00:00 | O34: ='Correlation Matrix'!E23 -> 0.011603838 | P34: =$B$2*P33+(1-$B$2)*O33^2 -> 0.00024863876 | T34: =N34 -> 28/03/2023 16:00:00 | U34: ='Correlation Matrix'!F23 -> -0.017055558 | V34: =$B$2*V33+(1-$B$2)*U33^2 -> 0.00035006829 | Z34: =T34 -> 28/03/2023 16:00:00 | AA34: ='Correlation Matrix'!G23 -> -0.00081811134 | AB34: =$B$2*AB33+(1-$B$2)*AA33^2 -> 0.0001290024 | AF34: =Z34 -> 28/03/2023 16:00:00 | AG34: ='Correlation Matrix'!H23 -> 0.0031834488 | AH34: =$B$2*AH33+(1-$B$2)*AG33^2 -> 0.00047058377 | AX34: ='Correlation Matrix'!B485 -> 30/01/2025 16:00:00 | AY34: ='Correlation Matrix'!C485 -> -0.0074221957 | AZ34: ='Correlation Matrix'!D485 -> -0.010303032 | BA34: ='Correlation Matrix'!E485 -> 0.0040383376 | BB34: ='Correlation Matrix'!F485 -> 0.046309334 | BC34: ='Correlation Matrix'!G485 -> 0.030877669 | BD34: ='Correlation Matrix'!H485 -> 0.055506886 | BE34: ='Correlation Matrix'!I485 -> 482
B35: ='Correlation Matrix'!B24 -> 29/03/2023 16:00:00 | C35: ='Correlation Matrix'!C24 -> 0.019597386 | D35: =$B$2*D34+(1-$B$2)*C34^2 -> 0.00016988078 | H35: =B35 -> 29/03/2023 16:00:00 | I35: ='Correlation Matrix'!D24 -> 0.030484917 | J35: =$B$2*J34+(1-$B$2)*I34^2 -> 0.00031162565 | N35: =H35 -> 29/03/2023 16:00:00 | O35: ='Correlation Matrix'!E24 -> 0.0085531971 | P35: =$B$2*P34+(1-$B$2)*O34^2 -> 0.00024179938 | T35: =N35 -> 29/03/2023 16:00:00 | U35: ='Correlation Matrix'!F24 -> 0.0557558 | V35: =$B$2*V34+(1-$B$2)*U34^2 -> 0.00034651772 | Z35: =T35 -> 29/03/2023 16:00:00 | AA35: ='Correlation Matrix'!G24 -> 0.014568941 | AB35: =$B$2*AB34+(1-$B$2)*AA34^2 -> 0.00012130241 | AF35: =Z35 -> 29/03/2023 16:00:00 | AG35: ='Correlation Matrix'!H24 -> 0.0048880473 | AH35: =$B$2*AH34+(1-$B$2)*AG34^2 -> 0.0004429568 | AX35: ='Correlation Matrix'!B484 -> 29/01/2025 16:00:00 | AY35: ='Correlation Matrix'!C484 -> 0.0046061804 | AZ35: ='Correlation Matrix'!D484 -> -0.0045452711 | BA35: ='Correlation Matrix'!E484 -> -0.0033344051 | BB35: ='Correlation Matrix'!F484 -> -0.0010527425 | BC35: ='Correlation Matrix'!G484 -> 0.0026273552 | BD35: ='Correlation Matrix'!H484 -> 0.04588234 | BE35: ='Correlation Matrix'!I484 -> 481
B36: ='Correlation Matrix'!B25 -> 30/03/2023 16:00:00 | C36: ='Correlation Matrix'!C25 -> 0.0098413198 | D36: =$B$2*D35+(1-$B$2)*C35^2 -> 0.00018273139 | H36: =B36 -> 30/03/2023 16:00:00 | I36: ='Correlation Matrix'!D25 -> 0.017305747 | J36: =$B$2*J35+(1-$B$2)*I35^2 -> 0.00034868792 | N36: =H36 -> 30/03/2023 16:00:00 | O36: ='Correlation Matrix'!E25 -> 0.009466428 | P36: =$B$2*P35+(1-$B$2)*O35^2 -> 0.00023168085 | T36: =N36 -> 30/03/2023 16:00:00 | U36: ='Correlation Matrix'!F25 -> 0.01862518 | V36: =$B$2*V35+(1-$B$2)*U35^2 -> 0.00051224921 | Z36: =T36 -> 30/03/2023 16:00:00 | AA36: ='Correlation Matrix'!G25 -> -0.00075126257 | AB36: =$B$2*AB35+(1-$B$2)*AA35^2 -> 0.00012675951 | AF36: =Z36 -> 30/03/2023 16:00:00 | AG36: ='Correlation Matrix'!H25 -> 0.012311878 | AH36: =$B$2*AH35+(1-$B$2)*AG35^2 -> 0.00041781297 | AX36: ='Correlation Matrix'!B483 -> 28/01/2025 16:00:00 | AY36: ='Correlation Matrix'!C483 -> 0.035892086 | AZ36: ='Correlation Matrix'!D483 -> 0.011529574 | BA36: ='Correlation Matrix'!E483 -> -0.0065084456 | BB36: ='Correlation Matrix'!F483 -> -0.024117593 | BC36: ='Correlation Matrix'!G483 -> -0.00051141554 | BD36: ='Correlation Matrix'!H483 -> 0.013723581 | BE36: ='Correlation Matrix'!I483 -> 480
B37: ='Correlation Matrix'!B26 -> 31/03/2023 16:00:00 | C37: ='Correlation Matrix'!C26 -> 0.015523138 | D37: =$B$2*D36+(1-$B$2)*C36^2 -> 0.0001775786 | H37: =B37 -> 31/03/2023 16:00:00 | I37: ='Correlation Matrix'!D26 -> 0.012567753 | J37: =$B$2*J36+(1-$B$2)*I36^2 -> 0.00034573598 | N37: =H37 -> 31/03/2023 16:00:00 | O37: ='Correlation Matrix'!E26 -> 0.004730465 | P37: =$B$2*P36+(1-$B$2)*O36^2 -> 0.00022315679 | T37: =N37 -> 31/03/2023 16:00:00 | U37: ='Correlation Matrix'!F26 -> 0.010238395 | V37: =$B$2*V36+(1-$B$2)*U36^2 -> 0.0005023281 | Z37: =T37 -> 31/03/2023 16:00:00 | AA37: ='Correlation Matrix'!G26 -> 0.011485313 | AB37: =$B$2*AB36+(1-$B$2)*AA36^2 -> 0.0001191878 | AF37: =Z37 -> 31/03/2023 16:00:00 | AG37: ='Correlation Matrix'!H26 -> 0.021633602 | AH37: =$B$2*AH36+(1-$B$2)*AG36^2 -> 0.00040183913 | AX37: ='Correlation Matrix'!B482 -> 27/01/2025 16:00:00 | AY37: ='Correlation Matrix'!C482 -> 0.031285691 | AZ37: ='Correlation Matrix'!D482 -> 0.0024241405 | BA37: ='Correlation Matrix'!E482 -> 0.010099805 | BB37: ='Correlation Matrix'!F482 -> -0.045576492 | BC37: ='Correlation Matrix'!G482 -> 0.02617781 | BD37: ='Correlation Matrix'!H482 -> -0.23382089 | BE37: ='Correlation Matrix'!I482 -> 479
B38: ='Correlation Matrix'!B27 -> 03/04/2023 16:00:00 | C38: ='Correlation Matrix'!C27 -> 0.0076721311 | D38: =$B$2*D37+(1-$B$2)*C37^2 -> 0.00018138195 | H38: =B38 -> 03/04/2023 16:00:00 | I38: ='Correlation Matrix'!D27 -> -0.0085562019 | J38: =$B$2*J37+(1-$B$2)*I37^2 -> 0.00033446872 | N38: =H38 -> 03/04/2023 16:00:00 | O38: ='Correlation Matrix'!E27 -> 0.040772962 | P38: =$B$2*P37+(1-$B$2)*O37^2 -> 0.00021111002 | T38: =N38 -> 03/04/2023 16:00:00 | U38: ='Correlation Matrix'!F27 -> -0.012369834 | V38: =$B$2*V37+(1-$B$2)*U37^2 -> 0.00047847789 | Z38: =T38 -> 03/04/2023 16:00:00 | AA38: ='Correlation Matrix'!G27 -> 0.0083849891 | AB38: =$B$2*AB37+(1-$B$2)*AA37^2 -> 0.00011995128 | AF38: =Z38 -> 03/04/2023 16:00:00 | AG38: ='Correlation Matrix'!H27 -> -0.024240486 | AH38: =$B$2*AH37+(1-$B$2)*AG37^2 -> 0.00040580955 | AX38: ='Correlation Matrix'!B481 -> 24/01/2025 16:00:00 | AY38: ='Correlation Matrix'!C481 -> -0.0039423042 | AZ38: ='Correlation Matrix'!D481 -> -0.0024241405 | BA38: ='Correlation Matrix'!E481 -> -0.0023102109 | BB38: ='Correlation Matrix'!F481 -> -0.01866669 | BC38: ='Correlation Matrix'!G481 -> -0.0013674127 | BD38: ='Correlation Matrix'!H481 -> 0.0035175771 | BE38: ='Correlation Matrix'!I481 -> 478
B39: ='Correlation Matrix'!B28 -> 04/04/2023 16:00:00 | C39: ='Correlation Matrix'!C28 -> -0.0032549757 | D39: =$B$2*D38+(1-$B$2)*C38^2 -> 0.00017403073 | H39: =B39 -> 04/04/2023 16:00:00 | I39: ='Correlation Matrix'!D28 -> 0.01492565 | J39: =$B$2*J38+(1-$B$2)*I38^2 -> 0.00031879312 | N39: =H39 -> 04/04/2023 16:00:00 | O39: ='Correlation Matrix'!E28 -> -0.0053689028 | P39: =$B$2*P38+(1-$B$2)*O38^2 -> 0.00029818949 | T39: =N39 -> 04/04/2023 16:00:00 | U39: ='Correlation Matrix'!F28 -> -0.034367644 | V39: =$B$2*V38+(1-$B$2)*U38^2 -> 0.00045894999 | Z39: =T39 -> 04/04/2023 16:00:00 | AA39: ='Correlation Matrix'!G28 -> -0.007037558 | AB39: =$B$2*AB38+(1-$B$2)*AA38^2 -> 0.00011697268 | AF39: =Z39 -> 04/04/2023 16:00:00 | AG39: ='Correlation Matrix'!H28 -> -0.0078616757 | AH39: =$B$2*AH38+(1-$B$2)*AG38^2 -> 0.00041671705 | AX39: ='Correlation Matrix'!B480 -> 23/01/2025 16:00:00 | AY39: ='Correlation Matrix'!C480 -> -0.00075979355 | AZ39: ='Correlation Matrix'!D480 -> 0.0017430866 | BA39: ='Correlation Matrix'!E480 -> -0.0025606569 | BB39: ='Correlation Matrix'!F480 -> 0.00057809039 | BC39: ='Correlation Matrix'!G480 -> 0.013265693 | BD39: ='Correlation Matrix'!H480 -> 0.040524781 | BE39: ='Correlation Matrix'!I480 -> 477
B40: ='Correlation Matrix'!B29 -> 05/04/2023 16:00:00 | C40: ='Correlation Matrix'!C29 -> -0.011354444 | D40: =$B$2*D39+(1-$B$2)*C39^2 -> 0.00016422458 | H40: =B40 -> 05/04/2023 16:00:00 | I40: ='Correlation Matrix'!D29 -> -0.027799888 | J40: =$B$2*J39+(1-$B$2)*I39^2 -> 0.00031303203 | N40: =H40 -> 05/04/2023 16:00:00 | O40: ='Correlation Matrix'!E29 -> 0.0049569321 | P40: =$B$2*P39+(1-$B$2)*O39^2 -> 0.00028202762 | T40: =N40 -> 05/04/2023 16:00:00 | U40: ='Correlation Matrix'!F29 -> -0.02496869 | V40: =$B$2*V39+(1-$B$2)*U39^2 -> 0.00050228108 | Z40: =T40 -> 05/04/2023 16:00:00 | AA40: ='Correlation Matrix'!G29 -> -0.00030232654 | AB40: =$B$2*AB39+(1-$B$2)*AA39^2 -> 0.00011292596 | AF40: =Z40 -> 05/04/2023 16:00:00 | AG40: ='Correlation Matrix'!H29 -> 0.0062942773 | AH40: =$B$2*AH39+(1-$B$2)*AG39^2 -> 0.00039542238 | AX40: ='Correlation Matrix'!B479 -> 22/01/2025 16:00:00 | AY40: ='Correlation Matrix'!C479 -> 0.0053307179 | AZ40: ='Correlation Matrix'!D479 -> 0.018466556 | BA40: ='Correlation Matrix'!E479 -> -0.011632103 | BB40: ='Correlation Matrix'!F479 -> 0.017696135 | BC40: ='Correlation Matrix'!G479 -> -0.0016678674 | BD40: ='Correlation Matrix'!H479 -> 0.026917844 | BE40: ='Correlation Matrix'!I479 -> 476
B41: ='Correlation Matrix'!B30 -> 06/04/2023 16:00:00 | C41: ='Correlation Matrix'!C30 -> 0.0054808005 | D41: =$B$2*D40+(1-$B$2)*C40^2 -> 0.00016210651 | H41: =B41 -> 06/04/2023 16:00:00 | I41: ='Correlation Matrix'!D30 -> 0.0094507496 | J41: =$B$2*J40+(1-$B$2)*I40^2 -> 0.00034062014 | N41: =H41 -> 06/04/2023 16:00:00 | O41: ='Correlation Matrix'!E30 -> -0.013213833 | P41: =$B$2*P40+(1-$B$2)*O40^2 -> 0.00026658024 | T41: =N41 -> 06/04/2023 16:00:00 | U41: ='Correlation Matrix'!F30 -> 0.0026380268 | V41: =$B$2*V40+(1-$B$2)*U40^2 -> 0.00050955035 | Z41: =T41 -> 06/04/2023 16:00:00 | AA41: ='Correlation Matrix'!G30 -> -0.0063977275 | AB41: =$B$2*AB40+(1-$B$2)*AA40^2 -> 0.00010615588 | AF41: =Z41 -> 06/04/2023 16:00:00 | AG41: ='Correlation Matrix'!H30 -> 0.0059950655 | AH41: =$B$2*AH40+(1-$B$2)*AG40^2 -> 0.00037407411 | AX41: ='Correlation Matrix'!B478 -> 21/01/2025 16:00:00 | AY41: ='Correlation Matrix'!C478 -> -0.032436231 | AZ41: ='Correlation Matrix'!D478 -> 0.020892033 | BA41: ='Correlation Matrix'!E478 -> -0.020206499 | BB41: ='Correlation Matrix'!F478 -> 0.03615694 | BC41: ='Correlation Matrix'!G478 -> 0.0063832429 | BD41: ='Correlation Matrix'!H478 -> 0.022750981 | BE41: ='Correlation Matrix'!I478 -> 475
B42: ='Correlation Matrix'!B31 -> 10/04/2023 16:00:00 | C42: ='Correlation Matrix'!C31 -> -0.016101239 | D42: =$B$2*D41+(1-$B$2)*C41^2 -> 0.00015418247 | H42: =B42 -> 10/04/2023 16:00:00 | I42: ='Correlation Matrix'!D31 -> 0.001077217 | J42: =$B$2*J41+(1-$B$2)*I41^2 -> 0.00032554193 | N42: =H42 -> 10/04/2023 16:00:00 | O42: ='Correlation Matrix'!E31 -> 0.0038102088 | P42: =$B$2*P41+(1-$B$2)*O41^2 -> 0.00026106174 | T42: =N42 -> 10/04/2023 16:00:00 | U42: ='Correlation Matrix'!F31 -> 0.078855007 | V42: =$B$2*V41+(1-$B$2)*U41^2 -> 0.00047939488 | Z42: =T42 -> 10/04/2023 16:00:00 | AA42: ='Correlation Matrix'!G31 -> -0.0036862059 | AB42: =$B$2*AB41+(1-$B$2)*AA41^2 -> 0.00010224239 | AF42: =Z42 -> 10/04/2023 16:00:00 | AG42: ='Correlation Matrix'!H31 -> 0.0047961723 | AH42: =$B$2*AH41+(1-$B$2)*AG41^2 -> 0.00035378611 | AX42: ='Correlation Matrix'!B477 -> 17/01/2025 16:00:00 | AY42: ='Correlation Matrix'!C477 -> 0.0075070185 | AZ42: ='Correlation Matrix'!D477 -> 0.023646422 | BA42: ='Correlation Matrix'!E477 -> 0.013028079 | BB42: ='Correlation Matrix'!F477 -> 0.012280138 | BC42: ='Correlation Matrix'!G477 -> 0.002977556 | BD42: ='Correlation Matrix'!H477 -> 0.0035465522 | BE42: ='Correlation Matrix'!I477 -> 474
B43: ='Correlation Matrix'!B32 -> 11/04/2023 16:00:00 | C43: ='Correlation Matrix'!C32 -> -0.0076201465 | D43: =$B$2*D42+(1-$B$2)*C42^2 -> 0.00016048651 | H43: =B43 -> 11/04/2023 16:00:00 | I43: ='Correlation Matrix'!D32 -> -0.022268227 | J43: =$B$2*J42+(1-$B$2)*I42^2 -> 0.00030607904 | N43: =H43 -> 11/04/2023 16:00:00 | O43: ='Correlation Matrix'!E32 -> 0.0055109618 | P43: =$B$2*P42+(1-$B$2)*O42^2 -> 0.0002462691 | T43: =N43 -> 11/04/2023 16:00:00 | U43: ='Correlation Matrix'!F32 -> 0.0086580627 | V43: =$B$2*V42+(1-$B$2)*U42^2 -> 0.00082371792 | Z43: =T43 -> 11/04/2023 16:00:00 | AA43: ='Correlation Matrix'!G32 -> 0.011018102 | AB43: =$B$2*AB42+(1-$B$2)*AA42^2 -> 9.6923129e-05 | AF43: =Z43 -> 11/04/2023 16:00:00 | AG43: ='Correlation Matrix'!H32 -> 0.0011631665 | AH43: =$B$2*AH42+(1-$B$2)*AG42^2 -> 0.00033393914 | AX43: ='Correlation Matrix'!B476 -> 16/01/2025 16:00:00 | AY43: ='Correlation Matrix'!C476 -> -0.041238976 | AZ43: ='Correlation Matrix'!D476 -> -0.012116992 | BA43: ='Correlation Matrix'!E476 -> 0.0066098255 | BB43: ='Correlation Matrix'!F476 -> -0.0059542317 | BC43: ='Correlation Matrix'!G476 -> 0.0015112534 | BD43: ='Correlation Matrix'!H476 -> 0.0469884 | BE43: ='Correlation Matrix'!I476 -> 473
